Workbook

Sheet Overview
A1: Smart Locker System - Database Schema Documentation
A2: Source: schema.production.sql | PostgreSQL 14+ | Multi-tenant IoT smart locker platform
A4: Summary (live formulas)
A5: Base tables + partitioned table | B5: =COUNTIF(Tables!C2:C15,"BASE TABLE")+COUNTIF(Tables!C2:C15,"PARTITIONED TABLE") -> 10
A6: Partitions | B6: =COUNTIF(Tables!C2:C15,"PARTITION") -> 4
A7: Columns documented (excl. partitions) | B7: =SUM(Tables!F2:F15) -> 103
A8: Relationships (total) | B8: =COUNTA(Relationships!B2:B19) -> 18
A9: of which enforced foreign keys | B9: =COUNTIF(Relationships!H2:H19,"Yes") -> 15
A10: of which logical (not enforced) | B10: =COUNTIF(Relationships!H2:H19,"No*") -> 3
A11: Constraints (PK / UNIQUE / CHECK) | B11: =SUM(Tables!I2:I15) -> 28
A12: Indexes (explicit) | B12: =SUM(Tables!J2:J15) -> 10
A13: Views | B13: =COUNTA(Views!A2:A3) -> 2
A14: Triggers | B14: =COUNTIF('Triggers & Functions'!B2:B7,"TRIGGER") -> 5
A16: Tenant hierarchy
A17: companies
A18: └── cities
A19: └── branches (also directly under companies)
A20: └── wards
A21: ├── kiosks
A22: └── lockers
A23: ├── locker_allocations (sessions; also → kiosks, employees, wards)
A24: ├── maintenance_tickets (→ employees as reporter / assignee)
A25: └── locker_events (partitioned, logical link only)
A26: companies ── employees (optionally → branches)
A28: Sheet guide
A29: Tables | B29: Index of all tables (click a name to jump to its sheet)
A30: Relationships | B30: Map of all 18 relationships across the schema
A31: <table name> sheets (10) | B31: One sheet per table: columns, relations, constraints, indexes and sample data
A32: Views | B32: Compatibility and analytics views
A33: Triggers & Functions | B33: updated_at automation
A34: Seed Data | B34: What schema.production.sql seeds by default
A35: Notes & Observations | B35: Review comments and potential improvements
A36: Test Credentials | B36: Plain-text logins and PINs matching the hashed dummy data

Sheet Tables
A1: Table | B1: Layer | C1: Type | D1: Purpose | E1: Primary Key | F1: # Columns | G1: # Outgoing refs (child of) | H1: # Incoming refs (parent of) | I1: # Constraints | J1: # Indexes (explicit)
A2: =HYPERLINK("#companies!A1","companies") -> companies | B2: 1 - Tenancy | C2: BASE TABLE | D2: Tenant / organization root of the hierarchy. Holds JSONB settings. | E2: id | F2: =COUNTA(companies!A8:A15) -> 8 | G2: =COUNTIF(Relationships!$B$2:$B$19,"companies") -> 0 | H2: =COUNTIF(Relationships!$D$2:$D$19,"companies") -> 3 | I2: =COUNTA(companies!A25:A27) -> 3 | J2: 0
A3: =HYPERLINK("#cities!A1","cities") -> cities | B3: 1 - Tenancy | C3: BASE TABLE | D3: Cities in which a company operates. | E3: id | F3: =COUNTA(cities!A8:A14) -> 7 | G3: =COUNTIF(Relationships!$B$2:$B$19,"cities") -> 1 | H3: =COUNTIF(Relationships!$D$2:$D$19,"cities") -> 1 | I3: =COUNTA(cities!A23:A24) -> 2 | J3: 0
A4: =HYPERLINK("#branches!A1","branches") -> branches | B4: 1 - Tenancy | C4: BASE TABLE | D4: Hospitals / facilities / campuses. | E4: id | F4: =COUNTA(branches!A8:A17) -> 10 | G4: =COUNTIF(Relationships!$B$2:$B$19,"branches") -> 2 | H4: =COUNTIF(Relationships!$D$2:$D$19,"branches") -> 2 | I4: =COUNTA(branches!A28:A29) -> 2 | J4: 0
A5: =HYPERLINK("#wards!A1","wards") -> wards | B5: 1 - Tenancy | C5: BASE TABLE | D5: Departments, floors or locker zones inside a branch. | E5: id | F5: =COUNTA(wards!A8:A15) -> 8 | G5: =COUNTIF(Relationships!$B$2:$B$19,"wards") -> 1 | H5: =COUNTIF(Relationships!$D$2:$D$19,"wards") -> 3 | I5: =COUNTA(wards!A26:A27) -> 2 | J5: 0
A6: =HYPERLINK("#kiosks!A1","kiosks") -> kiosks | B6: 2 - Hardware | C6: BASE TABLE | D6: User-facing touchscreen terminals. | E6: id | F6: =COUNTA(kiosks!A8:A18) -> 11 | G6: =COUNTIF(Relationships!$B$2:$B$19,"kiosks") -> 1 | H6: =COUNTIF(Relationships!$D$2:$D$19,"kiosks") -> 1 | I6: =COUNTA(kiosks!A27:A29) -> 3 | J6: =COUNTA(kiosks!A33:A33) -> 1
A7: =HYPERLINK("#lockers!A1","lockers") -> lockers | B7: 2 - Hardware | C7: BASE TABLE | D7: Physical locker compartments with IoT telemetry. | E7: id | F7: =COUNTA(lockers!A8:A20) -> 13 | G7: =COUNTIF(Relationships!$B$2:$B$19,"lockers") -> 1 | H7: =COUNTIF(Relationships!$D$2:$D$19,"lockers") -> 3 | I7: =COUNTA(lockers!A31:A34) -> 4 | J7: =COUNTA(lockers!A38:A38) -> 1
A8: =HYPERLINK("#employees!A1","employees") -> employees | B8: 3 - Users & RBAC | C8: BASE TABLE | D8: Staff accounts with role-based access. | E8: id | F8: =COUNTA(employees!A8:A19) -> 12 | G8: =COUNTIF(Relationships!$B$2:$B$19,"employees") -> 2 | H8: =COUNTIF(Relationships!$D$2:$D$19,"employees") -> 4 | I8: =COUNTA(employees!A32:A34) -> 3 | J8: =COUNTA(employees!A38:A39) -> 2
A9: =HYPERLINK("#locker_allocations!A1","locker_allocations") -> locker_allocations | B9: 4 - Sessions | C9: BASE TABLE | D9: One row per locker checkout lifecycle (audit + privacy). | E9: id | F9: =COUNTA(locker_allocations!A8:A22) -> 15 | G9: =COUNTIF(Relationships!$B$2:$B$19,"locker_allocations") -> 4 | H9: =COUNTIF(Relationships!$D$2:$D$19,"locker_allocations") -> 1 | I9: =COUNTA(locker_allocations!A34:A36) -> 3 | J9: =COUNTA(locker_allocations!A40:A42) -> 3
A10: =HYPERLINK("#maintenance_tickets!A1","maintenance_tickets") -> maintenance_tickets | B10: 5 - Maintenance | C10: BASE TABLE | D10: Fault / repair tickets for lockers. | E10: id | F10: =COUNTA(maintenance_tickets!A8:A18) -> 11 | G10: =COUNTIF(Relationships!$B$2:$B$19,"maintenance_tickets") -> 3 | H10: =COUNTIF(Relationships!$D$2:$D$19,"maintenance_tickets") -> 0 | I10: =COUNTA(maintenance_tickets!A28:A31) -> 4 | J10: 0
A11: =HYPERLINK("#locker_events!A1","locker_events") -> locker_events | B11: 6 - Audit / IoT | C11: PARTITIONED TABLE | D11: High-volume event log, RANGE-partitioned monthly on created_at. | E11: (id, created_at) | F11: =COUNTA(locker_events!A8:A15) -> 8 | G11: =COUNTIF(Relationships!$B$2:$B$19,"locker_events") -> 3 | H11: =COUNTIF(Relationships!$D$2:$D$19,"locker_events") -> 0 | I11: =COUNTA(locker_events!A25:A26) -> 2 | J11: =COUNTA(locker_events!A30:A32) -> 3
A12: locker_events_2026_10 | B12: 6 - Audit / IoT | C12: PARTITION | D12: Oct 2026 partition of locker_events. | E12: inherited | F12: - | G12: - | H12: - | I12: - | J12: -
A13: locker_events_2026_11 | B13: 6 - Audit / IoT | C13: PARTITION | D13: Nov 2026 partition of locker_events. | E13: inherited | F13: - | G13: - | H13: - | I13: - | J13: -
A14: locker_events_2026_12 | B14: 6 - Audit / IoT | C14: PARTITION | D14: Dec 2026 partition of locker_events. | E14: inherited | F14: - | G14: - | H14: - | I14: - | J14: -
A15: locker_events_default | B15: 6 - Audit / IoT | C15: PARTITION | D15: Catch-all DEFAULT partition. | E15: inherited | F15: - | G15: - | H15: - | I15: - | J15: -

Sheet Relationships
A1: # | B1: Child Table (FK side) | C1: Child Column | D1: Parent Table (referenced) | E1: Parent Column | F1: ON DELETE | G1: Cardinality | H1: Enforced FK? | I1: Meaning
A2: 1 | B2: cities | C2: company_id | D2: companies | E2: id | F2: CASCADE | G2: Many-to-One (N:1) | H2: Yes | I2: A company has many cities.
A3: 2 | B3: branches | C3: company_id | D3: companies | E3: id | F3: CASCADE | G3: Many-to-One (N:1) | H3: Yes | I3: A company has many branches.
A4: 3 | B4: branches | C4: city_id | D4: cities | E4: id | F4: CASCADE | G4: Many-to-One (N:1) | H4: Yes | I4: A city has many branches.
A5: 4 | B5: wards | C5: branch_id | D5: branches | E5: id | F5: CASCADE | G5: Many-to-One (N:1) | H5: Yes | I5: A branch has many wards.
A6: 5 | B6: kiosks | C6: ward_id | D6: wards | E6: id | F6: CASCADE | G6: Many-to-One (N:1) | H6: Yes | I6: A ward has many kiosks.
A7: 6 | B7: lockers | C7: ward_id | D7: wards | E7: id | F7: CASCADE | G7: Many-to-One (N:1) | H7: Yes | I7: A ward has many lockers.
A8: 7 | B8: employees | C8: company_id | D8: companies | E8: id | F8: CASCADE | G8: Many-to-One (N:1) | H8: Yes | I8: A company has many employees.
A9: 8 | B9: employees | C9: branch_id | D9: branches | E9: id | F9: SET NULL | G9: Many-to-One (N:1), optional | H9: Yes | I9: A branch has many employees; NULL = not branch-bound.
A10: 9 | B10: locker_allocations | C10: locker_id | D10: lockers | E10: id | F10: CASCADE | G10: Many-to-One (N:1) | H10: Yes | I10: A locker has many allocation sessions over time (max 1 active).
A11: 10 | B11: locker_allocations | C11: ward_id | D11: wards | E11: id | F11: CASCADE | G11: Many-to-One (N:1) | H11: Yes | I11: Ward copy for fast filtering.
A12: 11 | B12: locker_allocations | C12: kiosk_id | D12: kiosks | E12: id | F12: SET NULL | G12: Many-to-One (N:1), optional | H12: Yes | I12: Kiosk that created the allocation.
A13: 12 | B13: locker_allocations | C13: released_by_employee_id | D13: employees | E13: id | F13: SET NULL | G13: Many-to-One (N:1), optional | H13: Yes | I13: Employee who released the locker.
... A19: 18 | B19: locker_events | C19: actor_employee_id | D19: employees | E19: id | F19: n/a | G19: Many-to-One (N:1), optional | H19: No (logical) | I19: Employee who triggered the event.

Sheet companies
A1: Table: companies
A2: Tenant / organization root of the hierarchy. Holds JSONB settings.
A3: Layer: 1 - Tenancy | Type: BASE TABLE | Primary key: id
A4: =HYPERLINK("#Tables!A1","<< Back to Tables index") -> << Back to Tables index
A6: 1. COLUMNS
A7: Column | B7: Data Type | C7: Nullable | D7: Default | E7: Key / Constraint | F7: Description
A8: id | B8: SERIAL | C8: NO | D8: auto-increment | E8: PK | F8: Internal surrogate key for the tenant.
A9: uuid | B9: UUID | C9: NO | D9: gen_random_uuid() | E9: UQ | F9: Public/external identifier safe to expose in APIs.
A10: name | B10: VARCHAR(150) | C10: NO | F10: Organization display name.
A11: slug | B11: VARCHAR(100) | C11: NO | E11: UQ | F11: URL-friendly unique tenant code.
A12: settings | B12: JSONB | C12: NO | D12: {pin_length:4, max_occupancy_hours:24, photo_retention_days:7, require_occupant_phone:false, auto_unlock_on_timeout:false} | F12: Per-tenant configuration (PIN rules, occupancy limits, GDPR photo retention).
A13: is_active | B13: BOOLEAN | C13: NO | D13: TRUE | F13: Soft enable/disable flag for the tenant.
A14: created_at | B14: TIMESTAMPTZ | C14: NO | D14: CURRENT_TIMESTAMP | F14: Row creation time.
A15: updated_at | B15: TIMESTAMPTZ | C15: NO | D15: CURRENT_TIMESTAMP | F15: Auto-updated by trigger.
A17: 2. RELATIONSHIPS
A18: Direction | B18: This column | C18: Related table | D18: Related column | E18: ON DELETE | F18: Cardinality / meaning
A19: Referenced by (child) <- | B19: id | C19: cities | D19: company_id | E19: CASCADE | F19: Many-to-One (N:1); enforced FK: Yes. A company has many cities.
A20: Referenced by (child) <- | B20: id | C20: branches | D20: company_id | E20: CASCADE | F20: Many-to-One (N:1); enforced FK: Yes. A company has many branches.
A21: Referenced by (child) <- | B21: id | C21: employees | D21: company_id | E21: CASCADE | F21: Many-to-One (N:1); enforced FK: Yes. A company has many employees.
A23: 3. CONSTRAINTS
A24: Name | B24: Type | C24: Definition / columns | F24: Purpose
A25: companies_pkey | B25: PRIMARY KEY | C25: (id) | F25: Unique row identifier.
A26: companies_uuid_key | B26: UNIQUE | C26: uuid | F26: Public UUID must be unique.
A27: companies_slug_key | B27: UNIQUE | C27: slug | F27: Slug must be unique.
A29: 4. INDEXES
A30: Index name | B30: Type | C30: Columns / expression | F30: Purpose
A31: (none) | F31: Only implicit PK / UNIQUE indexes.
A33: 5. SAMPLE (DUMMY) DATA - 3 rows
A34: id | B34: uuid | C34: name | D34: slug | E34: settings | F34: is_active | G34: created_at | H34: updated_at
A35: 1 | B35: 6ae48192-5769-594e-95ea-0971a58330a5 | C35: Apex Health Systems | D35: apex-health | E35: {"pin_length": 4, "max_occupancy_hours": 24, "photo_retention_days": 7, "require_occupant_phone": false, "auto_unlock_on_timeout": false} | F35: =TRUE() -> TRUE | G35: 46032.375 | H35: 46032.375
A36: 2 | B36: 065a2cc1-9523-59c0-88af-bcb2dd5cde37 | C36: FitZone Gyms | D36: fitzone-gyms | E36: {"pin_length": 6, "max_occupancy_hours": 6, "photo_retention_days": 3, "require_occupant_phone": true, "auto_unlock_on_timeout": true} | F36: =TRUE() -> TRUE | G36: 46032.375 | H36: 46032.375
A37: 3 | B37: 5dadaa3f-01b2-5aeb-9b66-48c5b935c368 | C37: Urban Corp Facilities | D37: urban-corp | E37: {"pin_length": 4, "max_occupancy_hours": 12, "photo_retention_days": 14, "require_occupant_phone": false, "auto_unlock_on_timeout": false} | F37: =TRUE() -> TRUE | G37: 46032.375 | H37: 46032.375

Sheet cities
A1: Table: cities
A2: Cities in which a company operates.
A3: Layer: 1 - Tenancy | Type: BASE TABLE | Primary key: id
A4: =HYPERLINK("#Tables!A1","<< Back to Tables index") -> << Back to Tables index
A6: 1. COLUMNS
A7: Column | B7: Data Type | C7: Nullable | D7: Default | E7: Key / Constraint | F7: Description
A8: id | B8: SERIAL | C8: NO | D8: auto-increment | E8: PK | F8: City key.
A9: company_id | B9: INT | C9: NO | E9: FK → companies.id | F9: Owning tenant.
A10: name | B10: VARCHAR(100) | C10: NO | E10: UQ (company_id, name) | F10: City name, unique within a company.
A11: state | B11: VARCHAR(100) | C11: YES | F11: State / province.
A12: country | B12: VARCHAR(3) | C12: NO | D12: 'USA' | F12: Country code.
A13: created_at | B13: TIMESTAMPTZ | C13: NO | D13: CURRENT_TIMESTAMP | F13: Row creation time.
A14: updated_at | B14: TIMESTAMPTZ | C14: NO | D14: CURRENT_TIMESTAMP | F14: Last update (no trigger attached).
A16: 2. RELATIONSHIPS
A17: Direction | B17: This column | C17: Related table | D17: Related column | E17: ON DELETE | F17: Cardinality / meaning
A18: References (parent) -> | B18: company_id | C18: companies | D18: id | E18: CASCADE | F18: Many-to-One (N:1); enforced FK: Yes. A company has many cities.
A19: Referenced by (child) <- | B19: id | C19: branches | D19: city_id | E19: CASCADE | F19: Many-to-One (N:1); enforced FK: Yes. A city has many branches.
A21: 3. CONSTRAINTS
A22: Name | B22: Type | C22: Definition / columns | F22: Purpose
A23: cities_pkey | B23: PRIMARY KEY | C23: (id) | F23: Unique row identifier.
A24: uq_company_city | B24: UNIQUE | C24: (company_id, name) | F24: City name unique per company.
A26: 4. INDEXES
A27: Index name | B27: Type | C27: Columns / expression | F27: Purpose
A28: (none) | F28: Only implicit PK / UNIQUE indexes.
A30: 5. SAMPLE (DUMMY) DATA - 6 rows
A31: id | B31: company_id | C31: name | D31: state | E31: country | F31: created_at | G31: updated_at
A32: 1 | B32: 1 | C32: Metro City | D32: NY | E32: USA | F32: 46032.375 | G32: 46032.375
A33: 2 | B33: 1 | C33: West Valley | D33: CA | E33: USA | F33: 46032.375 | G33: 46032.375
A34: 3 | B34: 2 | C34: Austin | D34: TX | E34: USA | F34: 46032.375 | G34: 46032.375
A35: 4 | B35: 2 | C35: Denver | D35: CO | E35: USA | F35: 46032.375 | G35: 46032.375
A36: 5 | B36: 3 | C36: Chicago | D36: IL | E36: USA | F36: 46032.375 | G36: 46032.375
A37: 6 | B37: 3 | C37: Seattle | D37: WA | E37: USA | F37: 46032.375 | G37: 46032.375

Sheet branches
A1: Table: branches
A2: Hospitals / facilities / campuses.
A3: Layer: 1 - Tenancy | Type: BASE TABLE | Primary key: id
A4: =HYPERLINK("#Tables!A1","<< Back to Tables index") -> << Back to Tables index
A6: 1. COLUMNS
A7: Column | B7: Data Type | C7: Nullable | D7: Default | E7: Key / Constraint | F7: Description
A8: id | B8: SERIAL | C8: NO | D8: auto-increment | E8: PK | F8: Branch key.
A9: company_id | B9: INT | C9: NO | E9: FK → companies.id | F9: Owning tenant.
A10: city_id | B10: INT | C10: NO | E10: FK → cities.id | F10: City where the branch is located.
A11: name | B11: VARCHAR(150) | C11: NO | F11: Hospital / facility / campus name.
A12: code | B12: VARCHAR(50) | C12: NO | E12: UQ | F12: Globally unique branch code, e.g. CMH-NYC.
A13: address | B13: TEXT | C13: YES | F13: Street address.
A14: timezone | B14: VARCHAR(50) | C14: NO | D14: 'UTC' | F14: IANA timezone, e.g. America/New_York.
A15: is_active | B15: BOOLEAN | C15: NO | D15: TRUE | F15: Soft enable/disable flag.
A16: created_at | B16: TIMESTAMPTZ | C16: NO | D16: CURRENT_TIMESTAMP | F16: Row creation time.
A17: updated_at | B17: TIMESTAMPTZ | C17: NO | D17: CURRENT_TIMESTAMP | F17: Auto-updated by trigger.
A19: 2. RELATIONSHIPS
A20: Direction | B20: This column | C20: Related table | D20: Related column | E20: ON DELETE | F20: Cardinality / meaning
A21: References (parent) -> | B21: company_id | C21: companies | D21: id | E21: CASCADE | F21: Many-to-One (N:1); enforced FK: Yes. A company has many branches.
A22: References (parent) -> | B22: city_id | C22: cities | D22: id | E22: CASCADE | F22: Many-to-One (N:1); enforced FK: Yes. A city has many branches.
A23: Referenced by (child) <- | B23: id | C23: wards | D23: branch_id | E23: CASCADE | F23: Many-to-One (N:1); enforced FK: Yes. A branch has many wards.
A24: Referenced by (child) <- | B24: id | C24: employees | D24: branch_id | E24: SET NULL | F24: Many-to-One (N:1), optional; enforced FK: Yes. A branch has many employees; NULL = not branch-bound.
A26: 3. CONSTRAINTS
A27: Name | B27: Type | C27: Definition / columns | F27: Purpose
A28: branches_pkey | B28: PRIMARY KEY | C28: (id) | F28: Unique row identifier.
A29: branches_code_key | B29: UNIQUE | C29: code | F29: Branch code globally unique.
A31: 4. INDEXES
A32: Index name | B32: Type | C32: Columns / expression | F32: Purpose
A33: (none) | F33: Only implicit PK / UNIQUE indexes.
A35: 5. SAMPLE (DUMMY) DATA - 6 rows
A36: id | B36: company_id | C36: city_id | D36: name | E36: code | F36: address | G36: timezone | H36: is_active | I36: created_at | J36: updated_at
A37: 1 | B37: 1 | C37: 1 | D37: Central Memorial Hospital | E37: CMH-01 | F37: 100 Medical Plaza Blvd, New York, NY | G37: America/New_York | H37: =TRUE() -> TRUE | I37: 46032.375 | J37: 46032.375
A38: 2 | B38: 1 | C38: 2 | D38: Westside Community Clinic | E38: WCC-02 | F38: 450 Sunset Ave, Los Angeles, CA | G38: America/Los_Angeles | H38: =TRUE() -> TRUE | I38: 46032.375 | J38: 46032.375
A39: 3 | B39: 2 | C39: 3 | D39: FitZone Austin Downtown | E39: FZ-AUS-01 | F39: 210 Congress Ave, Austin, TX | G39: America/Chicago | H39: =TRUE() -> TRUE | I39: 46032.375 | J39: 46032.375
A40: 4 | B40: 2 | C40: 4 | D40: FitZone Denver Central | E40: FZ-DEN-01 | F40: 88 Larimer St, Denver, CO | G40: America/Denver | H40: =TRUE() -> TRUE | I40: 46032.375 | J40: 46032.375
A41: 5 | B41: 3 | C41: 5 | D41: Urban Tower Chicago | E41: URB-CHI-01 | F41: 330 N Wabash Ave, Chicago, IL | G41: America/Chicago | H41: =TRUE() -> TRUE | I41: 46032.375 | J41: 46032.375
A42: 6 | B42: 3 | C42: 6 | D42: Urban Plaza Seattle | E42: URB-SEA-01 | F42: 1201 Third Ave, Seattle, WA | G42: America/Los_Angeles | H42: =TRUE() -> TRUE | I42: 46032.375 | J42: 46032.375

Sheet wards
A1: Table: wards
A2: Departments, floors or locker zones inside a branch.
A3: Layer: 1 - Tenancy | Type: BASE TABLE | Primary key: id
A4: =HYPERLINK("#Tables!A1","<< Back to Tables index") -> << Back to Tables index
A6: 1. COLUMNS
A7: Column | B7: Data Type | C7: Nullable | D7: Default | E7: Key / Constraint | F7: Description
A8: id | B8: SERIAL | C8: NO | D8: auto-increment | E8: PK | F8: Ward key.
A9: branch_id | B9: INT | C9: NO | E9: FK → branches.id | F9: Parent branch.
A10: name | B10: VARCHAR(100) | C10: NO | E10: UQ (branch_id, name) | F10: Ward / department / locker zone name.
A11: floor | B11: VARCHAR(50) | C11: NO | D11: '1st Floor' | F11: Floor label.
A12: description | B12: TEXT | C12: YES | F12: Free-text description.
A13: is_active | B13: BOOLEAN | C13: NO | D13: TRUE | F13: Soft enable/disable flag.
A14: created_at | B14: TIMESTAMPTZ | C14: NO | D14: CURRENT_TIMESTAMP | F14: Row creation time.
A15: updated_at | B15: TIMESTAMPTZ | C15: NO | D15: CURRENT_TIMESTAMP | F15: Auto-updated by trigger.
A17: 2. RELATIONSHIPS
A18: Direction | B18: This column | C18: Related table | D18: Related column | E18: ON DELETE | F18: Cardinality / meaning
A19: References (parent) -> | B19: branch_id | C19: branches | D19: id | E19: CASCADE | F19: Many-to-One (N:1); enforced FK: Yes. A branch has many wards.
A20: Referenced by (child) <- | B20: id | C20: kiosks | D20: ward_id | E20: CASCADE | F20: Many-to-One (N:1); enforced FK: Yes. A ward has many kiosks.
A21: Referenced by (child) <- | B21: id | C21: lockers | D21: ward_id | E21: CASCADE | F21: Many-to-One (N:1); enforced FK: Yes. A ward has many lockers.
A22: Referenced by (child) <- | B22: id | C22: locker_allocations | D22: ward_id | E22: CASCADE | F22: Many-to-One (N:1); enforced FK: Yes. Ward copy for fast filtering.
A24: 3. CONSTRAINTS
A25: Name | B25: Type | C25: Definition / columns | F25: Purpose
A26: wards_pkey | B26: PRIMARY KEY | C26: (id) | F26: Unique row identifier.
A27: uq_branch_ward | B27: UNIQUE | C27: (branch_id, name) | F27: Ward name unique per branch.
A29: 4. INDEXES
A30: Index name | B30: Type | C30: Columns / expression | F30: Purpose
A31: (none) | F31: Only implicit PK / UNIQUE indexes.
A33: 5. SAMPLE (DUMMY) DATA - 10 rows
A34: id | B34: branch_id | C34: name | D34: floor | E34: description | F34: is_active | G34: created_at | H34: updated_at
A35: 1 | B35: 1 | C35: Ward 3A - Intensive Care | D35: 3rd Floor | E35: Inpatient surgical recovery & ICU storage | F35: =TRUE() -> TRUE | G35: 46032.375 | H35: 46032.375
A36: 2 | B36: 1 | C36: Ward 1B - Emergency Room | D36: 1st Floor | E36: Urgent trauma & ER public patient storage | F36: =TRUE() -> TRUE | G36: 46032.375 | H36: 46032.375
A37: 3 | B37: 2 | C37: Ward 2C - Outpatient Care | D37: 2nd Floor | E37: Outpatient procedures and staff lockers | F37: =TRUE() -> TRUE | G37: 46032.375 | H37: 46032.375
A38: 4 | B38: 2 | C38: Ward 1A - Reception | D38: 1st Floor | E38: Front desk visitor lockers | F38: =TRUE() -> TRUE | G38: 46032.375 | H38: 46032.375
A39: 5 | B39: 3 | C39: Men's Locker Room | D39: Ground Floor | E39: Gym members - men's changing area | F39: =TRUE() -> TRUE | G39: 46032.375 | H39: 46032.375
A40: 6 | B40: 3 | C40: Women's Locker Room | D40: Ground Floor | E40: Gym members - women's changing area | F40: =TRUE() -> TRUE | G40: 46032.375 | H40: 46032.375
A41: 7 | B41: 4 | C41: Main Locker Hall | D41: 1st Floor | E41: Shared locker hall near pool entrance | F41: =TRUE() -> TRUE | G41: 46032.375 | H41: 46032.375
A42: 8 | B42: 5 | C42: Lobby Lockers | D42: Ground Floor | E42: Visitor and courier lockers | F42: =TRUE() -> TRUE | G42: 46032.375 | H42: 46032.375
A43: 9 | B43: 5 | C43: Staff Lounge | D43: 5th Floor | E43: Employee personal lockers | F43: =TRUE() -> TRUE | G43: 46032.375 | H43: 46032.375
A44: 10 | B44: 6 | C44: Visitor Lockers | D44: Ground Floor | E44: Visitor storage by main entrance | F44: =TRUE() -> TRUE | G44: 46032.375 | H44: 46032.375

Sheet kiosks
A1: Table: kiosks
A2: User-facing touchscreen terminals.
A3: Layer: 2 - Hardware | Type: BASE TABLE | Primary key: id
A4: =HYPERLINK("#Tables!A1","<< Back to Tables index") -> << Back to Tables index
A6: 1. COLUMNS
A7: Column | B7: Data Type | C7: Nullable | D7: Default | E7: Key / Constraint | F7: Description
A8: id | B8: SERIAL | C8: NO | D8: auto-increment | E8: PK | F8: Kiosk key.
A9: ward_id | B9: INT | C9: NO | E9: FK → wards.id | F9: Ward where the kiosk is installed.
A10: kiosk_code | B10: VARCHAR(50) | C10: NO | E10: UQ | F10: Device code, e.g. KIOSK-3A-01.
A11: name | B11: VARCHAR(100) | C11: NO | F11: Friendly kiosk name.
A12: ip_address | B12: VARCHAR(45) | C12: YES | F12: IPv4/IPv6 address.
A13: mac_address | B13: VARCHAR(17) | C13: YES | F13: Hardware MAC address.
A14: app_version | B14: VARCHAR(20) | C14: YES | D14: '1.0.0' | F14: Installed kiosk app version.
A15: status | B15: VARCHAR(20) | C15: NO | D15: 'online' | E15: CHECK | F15: online | offline | maintenance.
A16: last_heartbeat | B16: TIMESTAMPTZ | C16: YES | F16: Last heartbeat received.
A17: created_at | B17: TIMESTAMPTZ | C17: NO | D17: CURRENT_TIMESTAMP | F17: Row creation time.
A18: updated_at | B18: TIMESTAMPTZ | C18: NO | D18: CURRENT_TIMESTAMP | F18: Last update (no trigger attached).
A20: 2. RELATIONSHIPS
A21: Direction | B21: This column | C21: Related table | D21: Related column | E21: ON DELETE | F21: Cardinality / meaning
A22: References (parent) -> | B22: ward_id | C22: wards | D22: id | E22: CASCADE | F22: Many-to-One (N:1); enforced FK: Yes. A ward has many kiosks.
A23: Referenced by (child) <- | B23: id | C23: locker_allocations | D23: kiosk_id | E23: SET NULL | F23: Many-to-One (N:1), optional; enforced FK: Yes. Kiosk that created the allocation.
A25: 3. CONSTRAINTS
A26: Name | B26: Type | C26: Definition / columns | F26: Purpose
A27: kiosks_pkey | B27: PRIMARY KEY | C27: (id) | F27: Unique row identifier.
A28: kiosks_kiosk_code_key | B28: UNIQUE | C28: kiosk_code | F28: Kiosk code globally unique.
A29: kiosks_status_check | B29: CHECK | C29: status IN ('online','offline','maintenance') | F29: Valid kiosk states.
A31: 4. INDEXES
A32: Index name | B32: Type | C32: Columns / expression | F32: Purpose
A33: idx_kiosks_ward_code | B33: B-tree | C33: (ward_id, kiosk_code) | F33: Kiosk lookups by ward and code.
A35: 5. SAMPLE (DUMMY) DATA - 10 rows
A36: id | B36: ward_id | C36: kiosk_code | D36: name | E36: ip_address | F36: mac_address | G36: app_version | H36: status | I36: last_heartbeat | J36: created_at | K36: updated_at
A37: 1 | B37: 1 | C37: KIOSK-3A-01 | D37: Ward 3A Main Entrance Terminal | E37: 192.168.1.101 | F37: A4:CF:12:11:23:35 | G37: 1.2.0 | H37: online | I37: 46309.333 | J37: 46032.375 | K37: 46309.333
A38: 2 | B38: 2 | C38: KIOSK-1B-01 | D38: ER Waiting Room Terminal | E38: 192.168.1.102 | F38: A4:CF:12:12:26:3A | G38: 1.1.4 | H38: online | I38: 46309.333 | J38: 46032.375 | K38: 46309.333
A39: 3 | B39: 3 | C39: KIOSK-2C-01 | D39: Outpatient Corridor Terminal | E39: 192.168.2.101 | F39: A4:CF:12:13:29:3F | G39: 1.2.0 | H39: online | I39: 46309.333 | J39: 46032.375 | K39: 46309.333
A40: 4 | B40: 4 | C40: KIOSK-1A-01 | D40: Reception Desk Terminal | E40: 192.168.2.102 | F40: A4:CF:12:14:2C:44 | G40: 1.1.4 | H40: maintenance | I40: 46309.333 | J40: 46032.375 | K40: 46309.333
A41: 5 | B41: 5 | C41: KIOSK-GYM-M01 | D41: Men's Locker Room Terminal | E41: 10.20.1.11 | F41: A4:CF:12:15:2F:49 | G41: 1.2.0 | H41: online | I41: 46309.333 | J41: 46032.375 | K41: 46309.333
A42: 6 | B42: 6 | C42: KIOSK-GYM-W01 | D42: Women's Locker Room Terminal | E42: 10.20.1.12 | F42: A4:CF:12:16:32:4E | G42: 1.1.4 | H42: online | I42: 46309.333 | J42: 46032.375 | K42: 46309.333
A43: 7 | B43: 7 | C43: KIOSK-DEN-01 | D43: Denver Main Hall Terminal | E43: 10.30.1.11 | F43: A4:CF:12:17:35:53 | G43: 1.2.0 | H43: online | I43: 46309.333 | J43: 46032.375 | K43: 46309.333
A44: 8 | B44: 8 | C44: KIOSK-CHI-L01 | D44: Chicago Lobby Terminal | E44: 172.16.5.21 | F44: A4:CF:12:18:38:58 | G44: 1.1.4 | H44: online | I44: 46309.333 | J44: 46032.375 | K44: 46309.333
A45: 9 | B45: 9 | C45: KIOSK-CHI-S01 | D45: Chicago Staff Lounge Terminal | E45: 172.16.5.22 | F45: A4:CF:12:19:3B:5D | G45: 1.2.0 | H45: offline | I45: 46307.92 | J45: 46032.375 | K45: 46309.333
...

Sheet lockers
A1: Table: lockers
A2: Physical locker compartments with IoT telemetry.
A3: Layer: 2 - Hardware | Type: BASE TABLE | Primary key: id
A4: =HYPERLINK("#Tables!A1","<< Back to Tables index") -> << Back to Tables index
A6: 1. COLUMNS
A7: Column | B7: Data Type | C7: Nullable | D7: Default | E7: Key / Constraint | F7: Description
A8: id | B8: SERIAL | C8: NO | D8: auto-increment | E8: PK | F8: Locker key.
A9: ward_id | B9: INT | C9: NO | E9: FK → wards.id | F9: Ward containing the locker.
A10: locker_number | B10: VARCHAR(50) | C10: NO | E10: UQ (ward_id, locker_number) | F10: Human label, e.g. L-101.
A11: status | B11: VARCHAR(20) | C11: NO | D11: 'available' | E11: CHECK | F11: available | occupied | unlocked | maintenance | offline.
A12: relay_channel | B12: INT | C12: YES | F12: Relay output index on controller board (1-32).
A13: battery_level | B13: INT | C13: YES | E13: CHECK | F13: 0-100 %.
A14: rssi | B14: INT | C14: YES | F14: Signal strength in dBm (-30 to -100).
A15: firmware_version | B15: VARCHAR(30) | C15: YES | D15: '1.0.0' | F15: Controller firmware.
A16: last_heartbeat | B16: TIMESTAMPTZ | C16: YES | F16: Last IoT heartbeat.
A17: is_enabled | B17: BOOLEAN | C17: NO | D17: TRUE | F17: Enable/disable the compartment.
A18: notes | B18: TEXT | C18: YES | F18: Free-text notes.
A19: created_at | B19: TIMESTAMPTZ | C19: NO | D19: CURRENT_TIMESTAMP | F19: Row creation time.
A20: updated_at | B20: TIMESTAMPTZ | C20: NO | D20: CURRENT_TIMESTAMP | F20: Auto-updated by trigger.
A22: 2. RELATIONSHIPS
A23: Direction | B23: This column | C23: Related table | D23: Related column | E23: ON DELETE | F23: Cardinality / meaning
A24: References (parent) -> | B24: ward_id | C24: wards | D24: id | E24: CASCADE | F24: Many-to-One (N:1); enforced FK: Yes. A ward has many lockers.
A25: Referenced by (child) <- | B25: id | C25: locker_allocations | D25: locker_id | E25: CASCADE | F25: Many-to-One (N:1); enforced FK: Yes. A locker has many allocation sessions over time (max 1 active).
A26: Referenced by (child) <- | B26: id | C26: maintenance_tickets | D26: locker_id | E26: CASCADE | F26: Many-to-One (N:1); enforced FK: Yes. A locker has many tickets.
A27: Referenced by (child) <- | B27: id | C27: locker_events | D27: locker_id | E27: n/a | F27: Many-to-One (N:1); enforced FK: No (logical). No FK because of partitioning / write throughput.
A29: 3. CONSTRAINTS
A30: Name | B30: Type | C30: Definition / columns | F30: Purpose
A31: lockers_pkey | B31: PRIMARY KEY | C31: (id) | F31: Unique row identifier.
A32: uq_ward_locker_number | B32: UNIQUE | C32: (ward_id, locker_number) | F32: Locker number unique per ward.
A33: lockers_status_check | B33: CHECK | C33: status IN ('available','occupied','unlocked','maintenance','offline') | F33: Valid locker states.
A34: lockers_battery_level_check | B34: CHECK | C34: battery_level BETWEEN 0 AND 100 | F34: Battery percentage range.
A36: 4. INDEXES
A37: Index name | B37: Type | C37: Columns / expression | F37: Purpose
A38: idx_lockers_ward_status | B38: B-tree | C38: (ward_id, status) | F38: Find first available locker in a ward quickly.
A40: 5. SAMPLE (DUMMY) DATA - 39 rows
A41: id | B41: ward_id | C41: locker_number | D41: status | E41: relay_channel | F41: battery_level | G41: rssi | H41: firmware_version | I41: last_heartbeat | J41: is_enabled | K41: notes | L41: created_at | M41: updated_at
A42: 101 | B42: 1 | C42: L-101 | D42: available | E42: 1 | F42: 68 | G42: -48 | H42: 1.1.0 | I42: 46309.334 | J42: =TRUE() -> TRUE | L42: 46032.375 | M42: 46309.333
A43: 102 | B43: 1 | C43: L-102 | D43: occupied | E43: 2 | F43: 61 | G43: -51 | H43: 1.0.2 | I43: 46309.335 | J43: =TRUE() -> TRUE | L43: 46032.375 | M43: 46309.333
A44: 103 | B44: 1 | C44: L-103 | D44: available | E44: 3 | F44: 99 | G44: -54 | H44: 1.1.0 | I44: 46309.335 | J44: =TRUE() -> TRUE | L44: 46032.375 | M44: 46309.333
A45: 104 | B45: 1 | C45: L-104 | D45: available | E45: 4 | F45: 92 | G45: -57 | H45: 1.1.0 | I45: 46309.336 | J45: =TRUE() -> TRUE | L45: 46032.375 | M45: 46309.333
...

Sheet employees
A1: Table: employees
A2: Staff accounts with role-based access.
A3: Layer: 3 - Users & RBAC | Type: BASE TABLE | Primary key: id
A4: =HYPERLINK("#Tables!A1","<< Back to Tables index") -> << Back to Tables index
A6: 1. COLUMNS
A7: Column | B7: Data Type | C7: Nullable | D7: Default | E7: Key / Constraint | F7: Description
A8: id | B8: SERIAL | C8: NO | D8: auto-increment | E8: PK | F8: Employee key.
A9: company_id | B9: INT | C9: NO | E9: FK → companies.id | F9: Employer tenant.
A10: branch_id | B10: INT | C10: YES | E10: FK → branches.id | F10: Home branch (NULL = company-wide).
A11: name | B11: VARCHAR(150) | C11: NO | F11: Full name.
A12: email | B12: VARCHAR(255) | C12: NO | E12: UQ | F12: Login identifier (globally unique).
A13: password_hash | B13: VARCHAR(255) | C13: NO | F13: Bcrypt password hash.
A14: role | B14: VARCHAR(30) | C14: NO | D14: 'staff' | E14: CHECK | F14: super_admin | company_admin | branch_admin | staff | technician.
A15: phone | B15: VARCHAR(50) | C15: YES | F15: Contact number.
A16: is_active | B16: BOOLEAN | C16: NO | D16: TRUE | F16: Account enabled flag.
A17: last_login_at | B17: TIMESTAMPTZ | C17: YES | F17: Last successful login.
A18: created_at | B18: TIMESTAMPTZ | C18: NO | D18: CURRENT_TIMESTAMP | F18: Row creation time.
A19: updated_at | B19: TIMESTAMPTZ | C19: NO | D19: CURRENT_TIMESTAMP | F19: Auto-updated by trigger.
A21: 2. RELATIONSHIPS
A22: Direction | B22: This column | C22: Related table | D22: Related column | E22: ON DELETE | F22: Cardinality / meaning
A23: References (parent) -> | B23: company_id | C23: companies | D23: id | E23: CASCADE | F23: Many-to-One (N:1); enforced FK: Yes. A company has many employees.
A24: References (parent) -> | B24: branch_id | C24: branches | D24: id | E24: SET NULL | F24: Many-to-One (N:1), optional; enforced FK: Yes. A branch has many employees; NULL = not branch-bound.
A25: Referenced by (child) <- | B25: id | C25: locker_allocations | D25: released_by_employee_id | E25: SET NULL | F25: Many-to-One (N:1), optional; enforced FK: Yes. Employee who released the locker.
A26: Referenced by (child) <- | B26: id | C26: maintenance_tickets | D26: reported_by_id | E26: SET NULL | F26: Many-to-One (N:1), optional; enforced FK: Yes. Employee who reported.
A27: Referenced by (child) <- | B27: id | C27: maintenance_tickets | D27: assigned_to_id | E27: SET NULL | F27: Many-to-One (N:1), optional; enforced FK: Yes. Technician assigned.
A28: Referenced by (child) <- | B28: id | C28: locker_events | D28: actor_employee_id | E28: n/a | F28: Many-to-One (N:1), optional; enforced FK: No (logical). Employee who triggered the event.
A30: 3. CONSTRAINTS
A31: Name | B31: Type | C31: Definition / columns | F31: Purpose
A32: employees_pkey | B32: PRIMARY KEY | C32: (id) | F32: Unique row identifier.
A33: employees_email_key | B33: UNIQUE | C33: email | F33: Email globally unique.
A34: employees_role_check | B34: CHECK | C34: role IN ('super_admin','company_admin','branch_admin','staff','technician') | F34: RBAC roles.
A36: 4. INDEXES
A37: Index name | B37: Type | C37: Columns / expression | F37: Purpose
A38: idx_employees_email | B38: B-tree | C38: (email) | F38: Login lookup (duplicates the UNIQUE index on email).
A39: idx_employees_branch | B39: B-tree | C39: (branch_id) | F39: List employees per branch.
A41: 5. SAMPLE (DUMMY) DATA - 12 rows
A42: id | B42: company_id | C42: branch_id | D42: name | E42: email | F42: password_hash | G42: role | H42: phone | I42: is_active | J42: last_login_at | K42: created_at | L42: updated_at
A43: 1 | B43: 1 | C43: 1 | D43: Sarah Connor | E43: admin@lockers.local | F43: $2b$10$w5K/5RDfSHGSn.rjo9vC3uz4wTbTGmGiCdykN8hjie8wKoXd3SjV2 | G43: super_admin | H43: +1-555-0201 | I43: =TRUE() -> TRUE | J43: 46309.33 | K43: 46032.375 | L43: 46309.333
A44: 2 | B44: 1 | C44: 1 | D44: Michael Scott | E44: branch@lockers.local | F44: $2b$10$svYlWp.cx9ZqulRG8TxePeOZPwEEQycCOmZP0P0Kc6ue1grWE7We. | G44: branch_admin | H44: +1-555-0202 | I44: =TRUE() -> TRUE | J44: 46309.312 | K44: 46032.375 | L44: 46309.333
A45: 3 | B45: 1 | C45: 1 | D45: Pam Beesly | E45: staff@lockers.local | F45: $2b$10$qnaEyFFSXpHvcp48KEVcluEYEwZRFS49QLwN9FVhVS8wqWEp2.SO6 | G45: staff | H45: +1-555-0203 | I45: =TRUE() -> TRUE | J45: 46309.281 | K45: 46032.375 | L45: 46309.333
...

Sheet locker_allocations
A1: Table: locker_allocations
A2: One row per locker checkout lifecycle (audit + privacy).
A3: Layer: 4 - Sessions | Type: BASE TABLE | Primary key: id
A4: =HYPERLINK("#Tables!A1","<< Back to Tables index") -> << Back to Tables index
A6: 1. COLUMNS
A7: Column | B7: Data Type | C7: Nullable | D7: Default | E7: Key / Constraint | F7: Description
A8: id | B8: BIGSERIAL | C8: NO | D8: auto-increment | E8: PK | F8: Allocation session key.
A9: locker_id | B9: INT | C9: NO | E9: FK → lockers.id | F9: Locker used in this session.
A10: ward_id | B10: INT | C10: NO | E10: FK → wards.id | F10: Ward (denormalized copy for fast filtering).
A11: kiosk_id | B11: INT | C11: YES | E11: FK → kiosks.id | F11: Kiosk that created the allocation.
A12: occupant_name | B12: VARCHAR(150) | C12: NO | F12: Person using the locker (PII).
A13: occupant_phone | B13: VARCHAR(50) | C13: YES | F13: Occupant phone (PII).
A14: pin_hash | B14: VARCHAR(255) | C14: YES | F14: Hashed access PIN.
A15: snapshot_path | B15: VARCHAR(500) | C15: YES | F15: Path/URL of camera photo (PII - auto-purge).
A16: status | B16: VARCHAR(20) | C16: NO | D16: 'active' | E16: CHECK | F16: active | completed | cancelled | forced_override | expired.
A17: allocated_at | B17: TIMESTAMPTZ | C17: NO | D17: CURRENT_TIMESTAMP | F17: Session start.
A18: released_at | B18: TIMESTAMPTZ | C18: YES | F18: Session end.
A19: released_by_type | B19: VARCHAR(30) | C19: YES | E19: CHECK | F19: occupant_pin | staff_override | timeout_auto | admin_remote.
A20: released_by_employee_id | B20: INT | C20: YES | E20: FK → employees.id | F20: Staff member who released it, if any.
A21: release_notes | B21: TEXT | C21: YES | F21: Notes on release.
A22: created_at | B22: TIMESTAMPTZ | C22: NO | D22: CURRENT_TIMESTAMP | F22: Row creation time.
A24: 2. RELATIONSHIPS
A25: Direction | B25: This column | C25: Related table | D25: Related column | E25: ON DELETE | F25: Cardinality / meaning
A26: References (parent) -> | B26: locker_id | C26: lockers | D26: id | E26: CASCADE | F26: Many-to-One (N:1); enforced FK: Yes. A locker has many allocation sessions over time (max 1 active).
A27: References (parent) -> | B27: ward_id | C27: wards | D27: id | E27: CASCADE | F27: Many-to-One (N:1); enforced FK: Yes. Ward copy for fast filtering.
A28: References (parent) -> | B28: kiosk_id | C28: kiosks | D28: id | E28: SET NULL | F28: Many-to-One (N:1), optional; enforced FK: Yes. Kiosk that created the allocation.
A29: References (parent) -> | B29: released_by_employee_id | C29: employees | D29: id | E29: SET NULL | F29: Many-to-One (N:1), optional; enforced FK: Yes. Employee who released the locker.
A30: Referenced by (child) <- | B30: id | C30: locker_events | D30: allocation_id | E30: n/a | F30: Many-to-One (N:1), optional; enforced FK: No (logical). Event tied to an allocation session.
A32: 3. CONSTRAINTS
A33: Name | B33: Type | C33: Definition / columns | F33: Purpose
A34: locker_allocations_pkey | B34: PRIMARY KEY | C34: (id) | F34: Unique row identifier.
A35: locker_allocations_status_check | B35: CHECK | C35: status IN ('active','completed','cancelled','forced_override','expired') | F35: Session states.
A36: locker_allocations_released_by_type_check | B36: CHECK | C36: released_by_type IN ('occupant_pin','staff_override','timeout_auto','admin_remote') | F36: How a locker was released.
A38: 4. INDEXES
A39: Index name | B39: Type | C39: Columns / expression | F39: Purpose
A40: uq_active_locker_allocation | B40: B-tree, UNIQUE, partial | C40: (locker_id) WHERE status='active' | F40: Enforces one active allocation per locker.
A41: idx_allocations_active_lookup | B41: B-tree, partial | C41: (locker_id, status) WHERE status='active' | F41: Active allocation lookup (overlaps with the unique partial index).
A42: idx_allocations_phone | B42: B-tree | C42: (occupant_phone) | F42: Search allocations by phone.
A44: 5. SAMPLE (DUMMY) DATA - 25 rows
A45: id | B45: locker_id | C45: ward_id | D45: kiosk_id | E45: occupant_name | F45: occupant_phone | G45: pin_hash | H45: snapshot_path | I45: status | J45: allocated_at | K45: released_at | L45: released_by_type | M45: released_by_employee_id | N45: release_notes | O45: created_at
...

Sheet maintenance_tickets
A1: Table: maintenance_tickets
A2: Fault / repair tickets for lockers.
A3: Layer: 5 - Maintenance | Type: BASE TABLE | Primary key: id
A4: =HYPERLINK("#Tables!A1","<< Back to Tables index") -> << Back to Tables index
A6: 1. COLUMNS
A7: Column | B7: Data Type | C7: Nullable | D7: Default | E7: Key / Constraint | F7: Description
A8: id | B8: SERIAL | C8: NO | D8: auto-increment | E8: PK | F8: Ticket key.
A9: locker_id | B9: INT | C9: NO | E9: FK → lockers.id | F9: Faulty locker.
A10: reported_by_id | B10: INT | C10: YES | E10: FK → employees.id | F10: Reporter.
A11: assigned_to_id | B11: INT | C11: YES | E11: FK → employees.id | F11: Assigned technician.
A12: issue_type | B12: VARCHAR(50) | C12: NO | E12: CHECK | F12: stuck_latch | relay_failure | sensor_fault | low_battery | physical_damage | connectivity_offline | other.
A13: severity | B13: VARCHAR(20) | C13: NO | D13: 'medium' | E13: CHECK | F13: low | medium | high | critical.
A14: status | B14: VARCHAR(20) | C14: NO | D14: 'open' | E14: CHECK | F14: open | in_progress | resolved | closed.
A15: description | B15: TEXT | C15: NO | F15: Problem description.
A16: resolution_notes | B16: TEXT | C16: YES | F16: How it was resolved.
A17: created_at | B17: TIMESTAMPTZ | C17: NO | D17: CURRENT_TIMESTAMP | F17: Ticket opened.
A18: resolved_at | B18: TIMESTAMPTZ | C18: YES | F18: Ticket resolved.
A20: 2. RELATIONSHIPS
A21: Direction | B21: This column | C21: Related table | D21: Related column | E21: ON DELETE | F21: Cardinality / meaning
A22: References (parent) -> | B22: locker_id | C22: lockers | D22: id | E22: CASCADE | F22: Many-to-One (N:1); enforced FK: Yes. A locker has many tickets.
A23: References (parent) -> | B23: reported_by_id | C23: employees | D23: id | E23: SET NULL | F23: Many-to-One (N:1), optional; enforced FK: Yes. Employee who reported.
A24: References (parent) -> | B24: assigned_to_id | C24: employees | D24: id | E24: SET NULL | F24: Many-to-One (N:1), optional; enforced FK: Yes. Technician assigned.
A26: 3. CONSTRAINTS
A27: Name | B27: Type | C27: Definition / columns | F27: Purpose
A28: maintenance_tickets_pkey | B28: PRIMARY KEY | C28: (id) | F28: Unique row identifier.
A29: maintenance_tickets_issue_type_check | B29: CHECK | C29: issue_type IN (stuck_latch, relay_failure, sensor_fault, low_battery, physical_damage, connectivity_offline, other) | F29: Issue categories.
A30: maintenance_tickets_severity_check | B30: CHECK | C30: severity IN ('low','medium','high','critical') | F30: Severity levels.
A31: maintenance_tickets_status_check | B31: CHECK | C31: status IN ('open','in_progress','resolved','closed') | F31: Ticket workflow.
A33: 4. INDEXES
A34: Index name | B34: Type | C34: Columns / expression | F34: Purpose
A35: (none) | F35: Only implicit PK / UNIQUE indexes.
A37: 5. SAMPLE (DUMMY) DATA - 8 rows
A38: id | B38: locker_id | C38: reported_by_id | D38: assigned_to_id | E38: issue_type | F38: severity | G38: status | H38: description | I38: resolution_notes | J38: created_at | K38: resolved_at
A39: 1 | B39: 105 | C39: 3 | D39: 5 | E39: low_battery | F39: medium | G39: in_progress | H39: Battery at 42% and latch needs inspection | J39: 46308.375
A40: 2 | B40: 304 | C40: 4 | D40: 5 | E40: connectivity_offline | F40: high | G40: open | H40: Locker controller has stopped sending heartbeats | J40: 46307.146
A41: 3 | B41: 704 | C41: 7 | D41: 11 | E41: sensor_fault | F41: medium | G41: open | H41: Door closed sensor intermittently reports open | J41: 46308.583
A42: 4 | B42: 204 | C42: 3 | D42: 5 | E42: stuck_latch | F42: critical | G42: resolved | H42: Latch jammed after forced override; door would not re-lock | I42: Replaced latch spring and re-calibrated relay | J42: 46308.576 | K42: 46309.312
A43: 5 | B43: 202 | C43: 3 | D43: 5 | E43: relay_failure | F43: high | G43: closed | H43: Relay channel 2 not firing on unlock command | I43: Swapped relay module, tested 20 cycles | J43: 46301.417 | K43: 46303.625
A44: 6 | B44: 901 | C44: 9 | D44: 10 | E44: physical_damage | F44: low | G44: closed | H44: Dent on locker door panel | I44: Panel straightened; cosmetic only | J44: 46297.396 | K44: 46300.5
A45: 7 | B45: 501 | C45: 6 | D45: 11 | E45: sensor_fault | F45: high | G45: open | H45: Occupancy sensor reports false positives | J45: 46309.326
...

Sheet locker_events
A1: Table: locker_events
A2: High-volume event log, RANGE-partitioned monthly on created_at. Partitions: 2026_10, 2026_11, 2026_12 + DEFAULT.
A3: Layer: 6 - Audit / IoT | Type: PARTITIONED TABLE | Primary key: (id, created_at)
A4: =HYPERLINK("#Tables!A1","<< Back to Tables index") -> << Back to Tables index
A6: 1. COLUMNS
A7: Column | B7: Data Type | C7: Nullable | D7: Default | E7: Key / Constraint | F7: Description
A8: id | B8: BIGSERIAL | C8: NO | D8: auto-increment | E8: PK (id, created_at) | F8: Event key (composite PK required by partitioning).
A9: locker_id | B9: INT | C9: NO | E9: Logical → lockers.id | F9: Locker the event relates to (no enforced FK).
A10: allocation_id | B10: BIGINT | C10: YES | E10: Logical → locker_allocations.id | F10: Related allocation session (no enforced FK).
A11: event_type | B11: VARCHAR(60) | C11: NO | F11: e.g. KIOSK_REGISTRATION, UNLOCK_COMMAND, DEVICE_ACK, DOOR_CLOSED, MANUAL_OVERRIDE.
A12: source | B12: VARCHAR(30) | C12: NO | D12: 'system' | E12: CHECK | F12: kiosk | admin | hardware_mqtt | system | cron.
A13: actor_employee_id | B13: INT | C13: YES | E13: Logical → employees.id | F13: Employee who triggered it (no enforced FK).
A14: details | B14: JSONB | C14: YES | D14: '{}' | F14: Free-form event payload (GIN indexed).
A15: created_at | B15: TIMESTAMPTZ | C15: NO | D15: CURRENT_TIMESTAMP | E15: PK (id, created_at) | F15: Event time; RANGE partition key.
A17: 2. RELATIONSHIPS
A18: Direction | B18: This column | C18: Related table | D18: Related column | E18: ON DELETE | F18: Cardinality / meaning
A19: References (parent) -> | B19: locker_id | C19: lockers | D19: id | E19: n/a | F19: Many-to-One (N:1); enforced FK: No (logical). No FK because of partitioning / write throughput.
A20: References (parent) -> | B20: allocation_id | C20: locker_allocations | D20: id | E20: n/a | F20: Many-to-One (N:1), optional; enforced FK: No (logical). Event tied to an allocation session.
A21: References (parent) -> | B21: actor_employee_id | C21: employees | D21: id | E21: n/a | F21: Many-to-One (N:1), optional; enforced FK: No (logical). Employee who triggered the event.
A23: 3. CONSTRAINTS
A24: Name | B24: Type | C24: Definition / columns | F24: Purpose
A25: locker_events_pkey | B25: PRIMARY KEY | C25: (id, created_at) | F25: Composite PK includes partition key.
A26: locker_events_source_check | B26: CHECK | C26: source IN ('kiosk','admin','hardware_mqtt','system','cron') | F26: Event origin.
A28: 4. INDEXES
A29: Index name | B29: Type | C29: Columns / expression | F29: Purpose
A30: idx_locker_events_created | B30: B-tree | C30: (created_at DESC) | F30: Latest-events queries.
A31: idx_locker_events_locker_id | B31: B-tree | C31: (locker_id) | F31: Events per locker.
A32: idx_locker_events_details_gin | B32: GIN | C32: USING gin (details) | F32: Search inside JSONB event payloads.
A34: 5. SAMPLE (DUMMY) DATA - 91 rows
A35: id | B35: locker_id | C35: allocation_id | D35: event_type | E35: source | F35: actor_employee_id | G35: details | H35: created_at
A36: 1 | B36: 702 | C36: 23 | D36: KIOSK_REGISTRATION | E36: kiosk | G36: {"occupant": "Mia Anderson", "phone": "+1-555-0702", "ward": "Main Locker Hall"} | H36: 46304.708
A37: 2 | B37: 702 | C37: 23 | D37: DEVICE_ACK | E37: hardware_mqtt | G37: {"status": "unlocked", "relayFired": true, "batteryLevel": 91} | H37: 46304.708
A38: 3 | B38: 702 | C38: 23 | D38: PIN_UNLOCK | E38: kiosk | G38: {"result": "success", "attempts": 1} | H38: 46304.75
A39: 4 | B39: 702 | C39: 23 | D39: ALLOCATION_RELEASED | E39: system | G39: {"releasedBy": "occupant_pin"} | H39: 46304.75
A40: 5 | B40: 401 | C40: 20 | D40: KIOSK_REGISTRATION | E40: kiosk | G40: {"occupant": "James Rodriguez", "phone": "+1-555-0401", "ward": "Ward 1A - Reception"} | H40: 46305.292
A41: 6 | B41: 401 | C41: 20 | D41: DEVICE_ACK | E41: hardware_mqtt | G41: {"status": "unlocked", "relayFired": true, "batteryLevel": 83} | H41: 46305.292
A42: 7 | B42: 401 | C42: 20 | D42: PIN_UNLOCK | E42: kiosk | G42: {"result": "success", "attempts": 1} | H42: 46305.375
A43: 8 | B43: 401 | C43: 20 | D43: ALLOCATION_RELEASED | E43: system | G43: {"releasedBy": "occupant_pin"} | H43: 46305.375
A44: 9 | B44: 103 | C44: 15 | D44: KIOSK_REGISTRATION | E44: kiosk | G44: {"occupant": "Emma Brown", "phone": "+1-555-0103", "ward": "Ward 3A - Intensive Care"} | H44: 46306.333
A45: 10 | B45: 103 | C45: 15 | D45: DEVICE_ACK | E45: hardware_mqtt | G45: {"status": "unlocked", "relayFired": true, "batteryLevel": 99} | H45: 46306.333
...

Sheet Views
A1: View | B1: Built From | C1: Purpose | D1: Output Columns
A2: v_active_lockers | B2: lockers, wards, branches, locker_allocations (LEFT JOIN on status='active') | C2: Drop-in compatibility view for the Express REST / Socket.IO API: each locker with its current occupant, ward and branch info. | D2: id, ward_id, locker_number, status, battery_level, last_heartbeat, relay_channel, firmware_version, is_enabled, current_allocation_id, occupant_name, occupant_phone, occupant_photo, pin_hash, allocated_at, ward_name, ward_floor, branch_id, branch_name
A3: v_ward_occupancy_summary | B3: wards, branches, lockers (LEFT JOIN) | C3: Per-ward analytics: counts by status and occupancy percentage. | D3: ward_id, ward_name, branch_id, branch_name, total_lockers, occupied_count, available_count, unlocked_count, maintenance_count, offline_count, occupancy_rate_percentage

Sheet Triggers & Functions
A1: Name | B1: Kind | C1: Table | D1: Timing | E1: Purpose
A2: update_timestamp_column() | B2: FUNCTION | C2: - | D2: - | E2: Sets NEW.updated_at = CURRENT_TIMESTAMP.
A3: trg_companies_updated | B3: TRIGGER | C3: companies | D3: BEFORE UPDATE, FOR EACH ROW | E3: Refresh updated_at.
A4: trg_branches_updated | B4: TRIGGER | C4: branches | D4: BEFORE UPDATE, FOR EACH ROW | E4: Refresh updated_at.
A5: trg_wards_updated | B5: TRIGGER | C5: wards | D5: BEFORE UPDATE, FOR EACH ROW | E5: Refresh updated_at.
A6: trg_lockers_updated | B6: TRIGGER | C6: lockers | D6: BEFORE UPDATE, FOR EACH ROW | E6: Refresh updated_at.
A7: trg_employees_updated | B7: TRIGGER | C7: employees | D7: BEFORE UPDATE, FOR EACH ROW | E7: Refresh updated_at.

Sheet Seed Data
A1: Table | B1: Rows Inserted | C1: Content
A2: companies | B2: 1 | C2: Apex Health Systems (slug apex-health)
A3: cities | B3: 2 | C3: Metro City NY; West Valley CA
A4: branches | B4: 2 | C4: Central Memorial Hospital (CMH-01); Westside Community Clinic (WCC-02)
A5: wards | B5: 3 | C5: Ward 3A ICU; Ward 1B ER (branch 1); Ward 2C Outpatient (branch 2)
A6: kiosks | B6: 2 | C6: KIOSK-3A-01 (ward 1); KIOSK-1B-01 (ward 2)
A7: lockers | B7: 7 | C7: L-101..L-105 in ward 1; L-201, L-202 in ward 2 (L-102, L-202 occupied; L-105 maintenance)
A8: employees | B8: 3 | C8: Sarah Connor (super_admin), Michael Scott (branch_admin), Pam Beesly (staff)
A9: locker_allocations | B9: 2 | C9: John Doe on L-102; Alice Smith on L-202 (both active)
A10: locker_events | B10: 3 | C10: KIOSK_REGISTRATION, DEVICE_ACK (locker 102); MAINTENANCE_FLAG (locker 105)
A11: Total rows | B11: =SUM(B2:B10) -> 25

Sheet Notes & Observations
A1: Area | B1: Observation
A2: Security | B2: Seed allocations store pin_hash as plain '1234' / '4321', although the column is documented as a bcrypt hash. Replace with real bcrypt hashes before use.
A3: Security | B3: All three seed employees share one identical bcrypt string; it is unlikely to match the passwords noted in the comments (Admin123!, Branch123!, Staff123!). Regenerate with bcrypt/pgcrypto crypt().
A4: Security | B4: v_active_lockers exposes pin_hash; consider removing it from the view or restricting access.
A5: Privacy | B5: The header promises auto-purge of PII photos (photo_retention_days) but no purge job/function exists in the schema; it must be implemented in the app or via cron.
A6: Integrity | B6: locker_events has no enforced foreign keys (locker_id, allocation_id, actor_employee_id). Orphan events are possible; this is a deliberate partitioning/throughput trade-off.
A7: Integrity | B7: locker_allocations.ward_id duplicates lockers.ward_id and is not checked for consistency.
A8: Integrity | B8: lockers.status is stored separately from allocation status; keep them in sync inside a transaction.
A9: Triggers | B9: cities and kiosks have updated_at columns but no update trigger.
A10: Indexes | B10: idx_employees_email duplicates the UNIQUE index on email; idx_allocations_active_lookup overlaps with uq_active_locker_allocation.
A11: Partitions | B11: Monthly partitions exist only for Oct-Dec 2026; automate creation (e.g. pg_partman). Creating a new partition fails if matching rows already sit in the DEFAULT partition.
A12: Design | B12: Tenant isolation is by hierarchy (ward > branch > company); lockers/kiosks carry no company_id, so tenant queries require joins.
A13: Design | B13: branches.code, kiosks.kiosk_code and employees.email are globally unique, not unique per company.

Sheet Test Credentials
A1: Employee ID | B1: Name | C1: Email (login) | D1: Role | E1: Password (plain, dummy only)
A2: 1 | B2: Sarah Connor | C2: admin@lockers.local | D2: super_admin | E2: Admin123!
A3: 2 | B3: Michael Scott | C3: branch@lockers.local | D3: branch_admin | E3: Branch123!
A4: 3 | B4: Pam Beesly | C4: staff@lockers.local | D4: staff | E4: Staff123!
A5: 4 | B5: Dwight Schrute | C5: dwight.schrute@lockers.local | D5: branch_admin | E5: Branch123!
A6: 5 | B6: Ryan Howard | C6: ryan.howard@lockers.local | D6: technician | E6: Tech123!
A7: 6 | B7: Jim Halpert | C7: jim.halpert@lockers.local | D7: branch_admin | E7: Branch123!
A8: 7 | B8: Angela Martin | C8: angela.martin@lockers.local | D8: staff | E8: Staff123!
A9: 8 | B9: Kevin Malone | C9: kevin.malone@lockers.local | D9: company_admin | E9: Admin123!
A10: 9 | B10: Oscar Martinez | C10: oscar.martinez@lockers.local | D10: branch_admin | E10: Branch123!
A11: 10 | B11: Stanley Hudson | C11: stanley.hudson@lockers.local | D11: technician | E11: Tech123!
A12: 11 | B12: Creed Bratton | C12: creed.bratton@lockers.local | D12: technician | E12: Tech123!
A13: 12 | B13: Toby Flenderson | C13: toby.flenderson@lockers.local | D13: staff | E13: Staff123!
A15: Locker PINs for dummy allocations (stored hashed in locker_allocations.pin_hash)
A16: Allocation ID | B16: Locker ID | C16: Occupant | D16: PIN (plain, dummy only) | E16: Allocation Status
A17: 1 | B17: 102 | C17: John Doe | D17: 1234 | E17: active
A18: 2 | B18: 202 | C18: Alice Smith | D18: 4321 | E18: active
A19: 3 | B19: 203 | C19: Robert Taylor | D19: 2468 | E19: active
A20: 4 | B20: 302 | C20: Charlotte Hall | D20: 1357 | E20: active
A21: 5 | B21: 403 | C21: Daniel Allen | D21: 9876 | E21: active
A22: 6 | B22: 501 | C22: Matthew Young | D22: 112233 | E22: active
A23: 7 | B23: 503 | C23: Amelia King | D23: 334455 | E23: active
A24: 8 | B24: 602 | C24: Harper Wright | D24: 556677 | E24: active
A25: 9 | B25: 701 | C25: Joseph Scott | D25: 778899 | E25: active
A26: 10 | B26: 802 | C26: Evelyn Green | D26: 9900 | E26: active
A27: 11 | B27: 901 | C27: David Baker | D27: 1470 | E27: active
A28: 12 | B28: 1002 | C28: Grace Adams | D28: 2580 | E28: active
... A41: 25 | B41: 102 | C41: Henry Moore | D41: 7975 | E41: completed
A43: Hashes in the Sample sheets / SQL are real bcrypt ($2b$, cost 10) of these values, so you can log in with them.
